I'm sorry, but an uncaught exception occurred.

While running game code:
  File "game/script.rpy", line 421, in script
    Unknown "Oui c’est bien moi ! Tu dois être [name]"
KeyError: u'name'

-- Full Traceback ------------------------------------------------------------

Full traceback:
  File "game/script.rpy", line 421, in script
    Unknown "Oui c’est bien moi ! Tu dois être [name]"
  File "D:\Isart\Game Week\renpy-6.99.14.3-sdk\renpy\ast.py", line 652, in execute
    renpy.exports.say(who, what, interact=self.interact, *args, **kwargs)
  File "D:\Isart\Game Week\renpy-6.99.14.3-sdk\renpy\exports.py", line 1180, in say
    who(what, *args, **kwargs)
  File "D:\Isart\Game Week\renpy-6.99.14.3-sdk\renpy\character.py", line 1003, in __call__
    what = what_pattern.replace("[what]", sub(what, translate=translate))
  File "D:\Isart\Game Week\renpy-6.99.14.3-sdk\renpy\character.py", line 985, in sub
    return renpy.substitutions.substitute(s, scope=scope, force=force, translate=translate)[0]
  File "D:\Isart\Game Week\renpy-6.99.14.3-sdk\renpy\substitutions.py", line 242, in substitute
    s = formatter.vformat(s, (), kwargs)
  File "/home/tom/ab/x64lucid-deps/install/lib/python2.7/string.py", line 563, in vformat
  File "/home/tom/ab/x64lucid-deps/install/lib/python2.7/string.py", line 585, in _vformat
  File "/home/tom/ab/x64lucid-deps/install/lib/python2.7/string.py", line 646, in get_field
  File "/home/tom/ab/x64lucid-deps/install/lib/python2.7/string.py", line 605, in get_value
KeyError: u'name'

Windows-8-6.2.9200
Ren'Py 6.99.14.3.3347
<3 Love Love Proba <3 Game_Week
Thu Apr 12 10:38:04 2018
